2025-04-13 03:19:57,413 - aiogram - INFO - Bot: –ë–æ—Ç –±—É—Ö–≥–∞–ª—Ç–µ—Ä [@Bu_online_bot]
2025-04-13 03:19:57,595 - aiogram - WARNING - Updates were skipped successfully.
2025-04-13 03:19:57,596 - aiogram.dispatcher.dispatcher - INFO - Start polling.
2025-04-13 03:20:18,371 - utils - WARNING - Attempt 1 failed: 
2025-04-13 03:20:30,363 - utils - WARNING - Attempt 2 failed: 
2025-04-13 03:21:16,360 - utils - WARNING - Attempt 3 failed: 
2025-04-13 03:24:46,604 - aiogram - INFO - Bot: –ë–æ—Ç –±—É—Ö–≥–∞–ª—Ç–µ—Ä [@Bu_online_bot]
2025-04-13 03:24:46,718 - aiogram - WARNING - Updates were skipped successfully.
2025-04-13 03:24:46,719 - aiogram.dispatcher.dispatcher - INFO - Start polling.
2025-04-13 03:25:09,373 - utils - WARNING - Attempt 1 failed: 
2025-04-13 03:25:21,372 - utils - WARNING - Attempt 2 failed: 
2025-04-13 03:25:33,378 - utils - WARNING - Attempt 3 failed: 
2025-04-13 03:29:41,911 - aiogram - INFO - Bot: –ë–æ—Ç –±—É—Ö–≥–∞–ª—Ç–µ—Ä [@Bu_online_bot]
2025-04-13 03:29:42,017 - aiogram - WARNING - Updates were skipped successfully.
2025-04-13 03:29:42,020 - aiogram.dispatcher.dispatcher - INFO - Start polling.
2025-04-13 03:30:00,757 - utils - ERROR - Tax calculation error: could not convert string to float: 'üßÆ –ù–∞–ª–æ–≥–æ–≤—ã–π –∫–∞–ª—å–∫—É–ª—è—Ç–æ—Ä'
2025-04-13 03:34:47,237 - aiogram - INFO - Bot: –ë–æ—Ç –±—É—Ö–≥–∞–ª—Ç–µ—Ä [@Bu_online_bot]
2025-04-13 03:34:47,348 - aiogram - WARNING - Updates were skipped successfully.
2025-04-13 03:34:47,350 - aiogram.dispatcher.dispatcher - INFO - Start polling.
2025-04-13 03:34:54,591 - utils - WARNING - Attempt 1 failed: Cannot connect to host api.deepseek.ai:443 ssl:default [getaddrinfo failed]
2025-04-13 03:34:55,595 - utils - WARNING - Attempt 2 failed: Cannot connect to host api.deepseek.ai:443 ssl:default [getaddrinfo failed]
2025-04-13 03:34:57,114 - utils - WARNING - Attempt 3 failed: Cannot connect to host api.deepseek.ai:443 ssl:default [getaddrinfo failed]
2025-04-13 03:39:14,449 - aiogram - INFO - Bot: –ë–æ—Ç –±—É—Ö–≥–∞–ª—Ç–µ—Ä [@Bu_online_bot]
2025-04-13 03:39:14,552 - aiogram - WARNING - Updates were skipped successfully.
2025-04-13 03:39:14,553 - aiogram.dispatcher.dispatcher - INFO - Start polling.
2025-04-13 03:39:27,836 - utils - WARNING - Attempt 1 failed: Cannot connect to host api.deepseek.ai:443 ssl:default [getaddrinfo failed]
2025-04-13 03:39:28,836 - utils - WARNING - Attempt 2 failed: Cannot connect to host api.deepseek.ai:443 ssl:default [getaddrinfo failed]
2025-04-13 03:39:30,341 - utils - WARNING - Attempt 3 failed: Cannot connect to host api.deepseek.ai:443 ssl:default [getaddrinfo failed]
2025-04-13 03:39:50,925 - aiogram.dispatcher.dispatcher - ERROR - Cause exception while getting updates.
Traceback (most recent call last):
  File "C:\Users\–í–æ–≤–∞\AppData\Local\Programs\Python\Python310\lib\site-packages\aiogram\bot\api.py", line 139, in make_request
    async with session.post(url, data=req, **kwargs) as response:
  File "C:\Users\–í–æ–≤–∞\AppData\Local\Programs\Python\Python310\lib\site-packages\aiohttp\client.py", line 1167, in __aenter__
    self._resp = await self._coro
  File "C:\Users\–í–æ–≤–∞\AppData\Local\Programs\Python\Python310\lib\site-packages\aiohttp\client.py", line 586, in _request
    await resp.start(conn)
  File "C:\Users\–í–æ–≤–∞\AppData\Local\Programs\Python\Python310\lib\site-packages\aiohttp\client_reqrep.py", line 905, in start
    message, payload = await protocol.read()  # type: ignore[union-attr]
  File "C:\Users\–í–æ–≤–∞\AppData\Local\Programs\Python\Python310\lib\site-packages\aiohttp\streams.py", line 616, in read
    await self._waiter
aiohttp.client_exceptions.ClientOSError: [WinError 1236] –ü–æ–¥–∫–ª—é—á–µ–Ω–∏–µ –∫ —Å–µ—Ç–∏ –±—ã–ª–æ —Ä–∞–∑–æ—Ä–≤–∞–Ω–æ –ª–æ–∫–∞–ª—å–Ω–æ–π —Å–∏—Å—Ç–µ–º–æ–π

During handling of the above exception, another exception occurred:

Traceback (most recent call last):
  File "C:\Users\–í–æ–≤–∞\AppData\Local\Programs\Python\Python310\lib\site-packages\aiogram\dispatcher\dispatcher.py", line 381, in start_polling
    updates = await self.bot.get_updates(
  File "C:\Users\–í–æ–≤–∞\AppData\Local\Programs\Python\Python310\lib\site-packages\aiogram\bot\bot.py", line 110, in get_updates
    result = await self.request(api.Methods.GET_UPDATES, payload)
  File "C:\Users\–í–æ–≤–∞\AppData\Local\Programs\Python\Python310\lib\site-packages\aiogram\bot\base.py", line 236, in request
    return await api.make_request(await self.get_session(), self.server, self.__token, method, data, files,
  File "C:\Users\–í–æ–≤–∞\AppData\Local\Programs\Python\Python310\lib\site-packages\aiogram\bot\api.py", line 142, in make_request
    raise exceptions.NetworkError(f"aiohttp client throws an error: {e.__class__.__name__}: {e}")
aiogram.utils.exceptions.NetworkError: Aiohttp client throws an error: ClientOSError: [WinError 1236] –ü–æ–¥–∫–ª—é—á–µ–Ω–∏–µ –∫ —Å–µ—Ç–∏ –±—ã–ª–æ —Ä–∞–∑–æ—Ä–≤–∞–Ω–æ –ª–æ–∫–∞–ª—å–Ω–æ–π —Å–∏—Å—Ç–µ–º–æ–π
2025-04-13 03:39:55,964 - aiogram.dispatcher.dispatcher - ERROR - Cause exception while getting updates.
Traceback (most recent call last):
  File "C:\Users\–í–æ–≤–∞\AppData\Local\Programs\Python\Python310\lib\site-packages\aiohttp\connector.py", line 1155, in _create_direct_connection
    hosts = await asyncio.shield(host_resolved)
  File "C:\Users\–í–æ–≤–∞\AppData\Local\Programs\Python\Python310\lib\site-packages\aiohttp\connector.py", line 874, in _resolve_host
    addrs = await self._resolver.resolve(host, port, family=self._family)
  File "C:\Users\–í–æ–≤–∞\AppData\Local\Programs\Python\Python310\lib\site-packages\aiohttp\resolver.py", line 33, in resolve
    infos = await self._loop.getaddrinfo(
  File "C:\Users\–í–æ–≤–∞\AppData\Local\Programs\Python\Python310\lib\asyncio\base_events.py", line 863, in getaddrinfo
    return await self.run_in_executor(
  File "C:\Users\–í–æ–≤–∞\AppData\Local\Programs\Python\Python310\lib\concurrent\futures\thread.py", line 58, in run
    result = self.fn(*self.args, **self.kwargs)
  File "C:\Users\–í–æ–≤–∞\AppData\Local\Programs\Python\Python310\lib\socket.py", line 955, in getaddrinfo
    for res in _socket.getaddrinfo(host, port, family, type, proto, flags):
socket.gaierror: [Errno 11004] getaddrinfo failed

The above exception was the direct cause of the following exception:

Traceback (most recent call last):
  File "C:\Users\–í–æ–≤–∞\AppData\Local\Programs\Python\Python310\lib\site-packages\aiogram\bot\api.py", line 139, in make_request
    async with session.post(url, data=req, **kwargs) as response:
  File "C:\Users\–í–æ–≤–∞\AppData\Local\Programs\Python\Python310\lib\site-packages\aiohttp\client.py", line 1167, in __aenter__
    self._resp = await self._coro
  File "C:\Users\–í–æ–≤–∞\AppData\Local\Programs\Python\Python310\lib\site-packages\aiohttp\client.py", line 562, in _request
    conn = await self._connector.connect(
  File "C:\Users\–í–æ–≤–∞\AppData\Local\Programs\Python\Python310\lib\site-packages\aiohttp\connector.py", line 540, in connect
    proto = await self._create_connection(req, traces, timeout)
  File "C:\Users\–í–æ–≤–∞\AppData\Local\Programs\Python\Python310\lib\site-packages\aiohttp\connector.py", line 901, in _create_connection
    _, proto = await self._create_direct_connection(req, traces, timeout)
  File "C:\Users\–í–æ–≤–∞\AppData\Local\Programs\Python\Python310\lib\site-packages\aiohttp\connector.py", line 1169, in _create_direct_connection
    raise ClientConnectorError(req.connection_key, exc) from exc
aiohttp.client_exceptions.ClientConnectorError: Cannot connect to host api.telegram.org:443 ssl:default [getaddrinfo failed]

During handling of the above exception, another exception occurred:

Traceback (most recent call last):
  File "C:\Users\–í–æ–≤–∞\AppData\Local\Programs\Python\Python310\lib\site-packages\aiogram\dispatcher\dispatcher.py", line 381, in start_polling
    updates = await self.bot.get_updates(
  File "C:\Users\–í–æ–≤–∞\AppData\Local\Programs\Python\Python310\lib\site-packages\aiogram\bot\bot.py", line 110, in get_updates
    result = await self.request(api.Methods.GET_UPDATES, payload)
  File "C:\Users\–í–æ–≤–∞\AppData\Local\Programs\Python\Python310\lib\site-packages\aiogram\bot\base.py", line 236, in request
    return await api.make_request(await self.get_session(), self.server, self.__token, method, data, files,
  File "C:\Users\–í–æ–≤–∞\AppData\Local\Programs\Python\Python310\lib\site-packages\aiogram\bot\api.py", line 142, in make_request
    raise exceptions.NetworkError(f"aiohttp client throws an error: {e.__class__.__name__}: {e}")
aiogram.utils.exceptions.NetworkError: Aiohttp client throws an error: ClientConnectorError: Cannot connect to host api.telegram.org:443 ssl:default [getaddrinfo failed]
2025-04-13 03:42:25,987 - aiogram - INFO - Bot: –ë–æ—Ç –±—É—Ö–≥–∞–ª—Ç–µ—Ä [@Bu_online_bot]
2025-04-13 03:42:26,102 - aiogram - WARNING - Updates were skipped successfully.
2025-04-13 03:42:26,105 - aiogram.dispatcher.dispatcher - INFO - Start polling.
2025-04-13 03:42:45,372 - utils - WARNING - Attempt 1 failed: 
2025-04-13 03:44:16,601 - aiogram - INFO - Bot: –ë–æ—Ç –±—É—Ö–≥–∞–ª—Ç–µ—Ä [@Bu_online_bot]
2025-04-13 03:44:16,713 - aiogram - WARNING - Updates were skipped successfully.
2025-04-13 03:44:16,716 - aiogram.dispatcher.dispatcher - INFO - Start polling.
2025-04-13 03:45:06,378 - utils - WARNING - Attempt 1 failed: 
2025-04-13 03:45:18,371 - utils - WARNING - Attempt 2 failed: 
2025-04-13 03:45:30,355 - utils - WARNING - Attempt 3 failed: 
2025-04-13 04:02:11,377 - aiogram - INFO - Bot: –ë–æ—Ç –±—É—Ö–≥–∞–ª—Ç–µ—Ä [@Bu_online_bot]
2025-04-13 04:02:11,660 - aiogram - WARNING - Updates were skipped successfully.
2025-04-13 04:02:11,661 - aiogram.dispatcher.dispatcher - INFO - Start polling.
2025-04-13 04:06:52,595 - aiogram - INFO - Bot: –ë–æ—Ç –±—É—Ö–≥–∞–ª—Ç–µ—Ä [@Bu_online_bot]
2025-04-13 04:06:52,712 - aiogram - WARNING - Updates were skipped successfully.
2025-04-13 04:06:52,714 - aiogram.dispatcher.dispatcher - INFO - Start polling.
2025-04-13 04:08:06,076 - aiogram - INFO - Bot: –ë–æ—Ç –±—É—Ö–≥–∞–ª—Ç–µ—Ä [@Bu_online_bot]
2025-04-13 04:08:06,243 - aiogram - WARNING - Updates were skipped successfully.
2025-04-13 04:08:06,247 - aiogram.dispatcher.dispatcher - INFO - Start polling.
